Workbook

Sheet Read Me
A1: Shoe Inventory Data Source Simulation
A2: Mock athletic / sport / casual footwear inventory across four store locations
A4: Purpose
A5: This workbook is a synthetic data source built to stand in for a real footwear inventory extract during design, demo, and integration testing. Every SKU, UPC, quantity, and store number in it is fabricated. It is not Hibbett data and carries no confidential information.
A7: Sheets
A8: Inventory Master — the fact table. One row per SKU (style / color / size), with on-hand units for each of the four stores.
A9: Style Master — the dimension table. One row per style-colorway, with the SKU count and total units rolled up by formula.
A10: Store Directory — the four store locations, their attributes, and their assortment / stocking profile.
A11: Store Summary — live SUMIFS roll-ups of units and retail value by brand and by category, per store.
A13: How to read the store columns
A14: A number (including 0) means the store is assorted for that SKU. 0 = assorted but currently out of stock.
A15: A blank cell means the store does not carry that SKU at all — it is not part of that store's assortment.
... A42: Sales Floor Units, Overstock Location, and Last Counted are generated values, not formulas. Overstock locations are only assigned where back room depth is six pairs or more.

Sheet Store Directory
A1: Store Directory
A3: Store Number | B3: Store Name | C3: City | D3: State | E3: Region | F3: Banner / Format | G3: Selling Sq Ft | H3: Date Opened | I3: Volume Index | J3: Assortment Depth | K3: SKUs Assorted | L3: Units On Hand | M3: On-Hand Retail Value
A4: 0146 | B4: Trussville Marketplace | C4: Trussville | D4: AL | E4: AL / North | F4: Hibbett Sports | G4: 5200 | H4: 40620 | I4: 1 | J4: Core chain assortment | K4: =COUNT('Inventory Master'!$T$2:$T$525) -> 443 | L4: =SUM('Inventory Master'!$T$2:$T$525) -> 1152 | M4: =SUMPRODUCT('Inventory Master'!$R$2:$R$525,'Inventory Master'!$T$2:$T$525) -> 128139.48
A5: 1382 | B5: Cartersville Pavilion | C5: Cartersville | D5: GA | E5: GA / Northwest | F5: Hibbett Sports | G5: 4400 | H5: 41853 | I5: 0.7 | J5: Reduced size runs | K5: =COUNT('Inventory Master'!$U$2:$U$525) -> 342 | L5: =SUM('Inventory Master'!$U$2:$U$525) -> 663 | M5: =SUMPRODUCT('Inventory Master'!$R$2:$R$525,'Inventory Master'!$U$2:$U$525) -> 75894.37
A6: 2071 | B6: Southaven Towne Center | C6: Southaven | D6: MS | E6: MS / Memphis Metro | F6: City Gear | G6: 6800 | H6: 40110 | I6: 1.35 | J6: Flagship / full depth | K6: =COUNT('Inventory Master'!$V$2:$V$525) -> 514 | L6: =SUM('Inventory Master'!$V$2:$V$525) -> 1831 | M6: =SUMPRODUCT('Inventory Master'!$R$2:$R$525,'Inventory Master'!$V$2:$V$525) -> 202513.69
A7: 3719 | B7: Florence Regency Square | C7: Florence | D7: SC | E7: SC / Pee Dee | F7: Hibbett Sports | G7: 3900 | H7: 43231 | I7: 0.55 | J7: Small-market, edited | K7: =COUNT('Inventory Master'!$W$2:$W$525) -> 248 | L7: =SUM('Inventory Master'!$W$2:$W$525) -> 375 | M7: =SUMPRODUCT('Inventory Master'!$R$2:$R$525,'Inventory Master'!$W$2:$W$525) -> 39906.25
A8: TOTAL | K8: =SUM(K4:K7) -> 1547 | L8: =SUM(L4:L7) -> 4021 | M8: =SUM(M4:M7) -> 446453.79
A10: SKUs Assorted counts store cells that contain a number (0 included); a blank means the SKU is not carried at that store. Volume Index is the relative on-hand depth multiplier used to generate the data.

Sheet Inventory Master
A1: SKU | B1: UPC | C1: Item ID | D1: Manufacturer | E1: Brand | F1: Model | G1: Style Number | H1: Product Description | I1: Category | J1: Sub-Category | K1: Gender | L1: Color | M1: Size | N1: Width | O1: Season | P1: Lifecycle Status | Q1: MSRP | R1: Current Retail | S1: Unit Cost | T1: Store 0146 On Hand | U1: Store 1382 On Hand | V1: Store 2071 On Hand | W1: Store 3719 On Hand | X1: Total On Hand | Y1: Stores Stocking | Z1: On-Hand Retail Value | AA1: Last Received
A2: HB-4102582 | B2: 877862873808 | C2: ITM-700225 | D2: adidas AG | E2: adidas | F2: Adilette Comfort Slide | G2: AU7200 | H2: adidas Adilette Comfort Slide "Core Black/White" Men's Shoe | I2: Sandals | J2: Slides | K2: Men | L2: Core Black/White | M2: 13 | N2: D - Medium | O2: FA26 | P2: Active | Q2: 34.99 | R2: 34.99 | S2: 19.22 | T2: 3 | U2: 0 | V2: 5 | X2: =SUM(T2:W2) -> 8 | Y2: =COUNT(T2:W2) -> 3 | Z2: =R2*X2 -> 279.92 | AA2: 46212
A3: HB-4100776 | B3: 817439334285 | C3: ITM-700140 | D3: Nike, Inc. | E3: Nike | F3: Revolution 7 | G3: TA0814-787 | H3: Nike Revolution 7 "Black/Off Noir/Dark Smoke Grey" Men's Shoe | I3: Running | J3: Entry Cushion | K3: Men | L3: Black/Off Noir/Dark Smoke Grey | M3: 12 | N3: D - Medium | O3: SP26 | P3: Active | Q3: 74.99 | R3: 74.99 | S3: 36.3 | T3: 0 | V3: 2 | X3: =SUM(T3:W3) -> 2 | Y3: =COUNT(T3:W3) -> 2 | Z3: =R3*X3 -> 149.98 | AA3: 46212
A4: HB-4103107 | B4: 840252722072 | C4: ITM-700247 | D4: New Balance Athletics, Inc. | E4: New Balance | F4: Fresh Foam Arishi v4 | G4: W8600KRG | H4: New Balance Fresh Foam Arishi v4 "Black/Silver" Men's Shoe | I4: Running | J4: Entry Cushion | K4: Men | L4: Black/Silver | M4: 11.5 | N4: D - Medium | O4: FA26 | P4: Active | Q4: 79.99 | R4: 79.99 | S4: 39.84 | T4: 2 | V4: 3 | X4: =SUM(T4:W4) -> 5 | Y4: =COUNT(T4:W4) -> 2 | Z4: =R4*X4 -> 399.95 | AA4: 46147
A5: HB-4103370 | B5: 824027160113 | C5: ITM-700264 | D5: Under Armour, Inc. | E5: Under Armour | F5: Surge 4 | G5: 3021004-318 | H5: Under Armour Surge 4 "Black/Red" Big Kids' Shoe | I5: Running | J5: Entry Cushion | K5: Big Kids | L5: Black/Red | M5: 5Y | N5: M - Medium | O5: SP26 | P5: Active | Q5: 64.99 | R5: 64.99 | S5: 32.11 | V5: 3 | X5: =SUM(T5:W5) -> 3 | Y5: =COUNT(T5:W5) -> 1 | Z5: =R5*X5 -> 194.97 | AA5: 46174
A6: HB-4101994 | B6: 811910052093 | C6: ITM-700194 | D6: adidas AG | E6: adidas Originals | F6: Handball Spezial | G6: YN8777 | H6: adidas Originals Handball Spezial "Blue/Gum" Men's Shoe | I6: Casual | J6: Terrace / Lifestyle | K6: Men | L6: Blue/Gum | M6: 9 | N6: D - Medium | O6: SU26 | P6: Active | Q6: 109.99 | R6: 109.99 | S6: 54.53 | T6: 2 | U6: 4 | V6: 3 | W6: 3 | X6: =SUM(T6:W6) -> 12 | Y6: =COUNT(T6:W6) -> 4 | Z6: =R6*X6 -> 1319.88 | AA6: 46142
A7: HB-4104772 | B7: 864758033155 | C7: ITM-700349 | D7: Mizuno Corporation | E7: Mizuno | F7: Ambition 4 Turf | G7: 212707-7648 | H7: Mizuno Ambition 4 Turf "Navy/White" Men's Shoe | I7: Baseball | J7: Turf Trainer | K7: Men | L7: Navy/White | M7: 9.5 | N7: D - Medium | O7: SU26 | P7: Active | Q7: 89.99 | R7: 89.99 | S7: 44.22 | T7: 3 | U7: 0 | V7: 7 | X7: =SUM(T7:W7) -> 10 | Y7: =COUNT(T7:W7) -> 3 | Z7: =R7*X7 -> 899.9 | AA7: 46142
A8: HB-4105167 | B8: 886681888719 | C8: ITM-700373 | D8: VF Corporation | E8: Vans | F8: Knu Skool | G8: VN000FMD01V | H8: Vans Knu Skool "Navy/White" Women's Shoe | I8: Casual | J8: Canvas / Skate | K8: Women | L8: Navy/White | M8: 8.5 | N8: B - Medium | O8: SP26 | P8: Active | Q8: 89.99 | R8: 89.99 | S8: 45.49 | T8: 4 | U8: 0 | V8: 4 | X8: =SUM(T8:W8) -> 8 | Y8: =COUNT(T8:W8) -> 3 | Z8: =R8*X8 -> 719.92 | AA8: 46111
A9: HB-4105459 | B9: 861021087424 | C9: ITM-700388 | D9: Crocs, Inc. | E9: Crocs | F9: Classic Clog | G9: 57800-178 | H9: Crocs Classic Clog "Bubblegum Pink" Little Kids' Shoe | I9: Sandals | J9: Clogs | K9: Little Kids | L9: Bubblegum Pink | M9: 2Y | N9: M - Medium | O9: FA26 | P9: Pre-Season | Q9: 44.99 | R9: 44.99 | S9: 22.09 | T9: 3 | U9: 5 | V9: 4 | W9: 6 | X9: =SUM(T9:W9) -> 18 | Y9: =COUNT(T9:W9) -> 4 | Z9: =R9*X9 -> 809.82 | AA9: 46188
A10: HB-4105056 | B10: 848859341885 | C10: ITM-700366 | D10: VF Corporation | E10: Vans | F10: Classic Slip-On | G10: VN000TBP59A | H10: Vans Classic Slip-On "Black/White Checkerboard" Unisex Shoe | I10: Casual | J10: Canvas / Skate | K10: Unisex | L10: Black/White Checkerboard | M10: 10 | N10: M - Medium | O10: SP26 | P10: Active | Q10: 69.99 | R10: 69.99 | S10: 37.84 | T10: 4 | U10: 2 | V10: 4 | W10: 0 | X10: =SUM(T10:W10) -> 10 | Y10: =COUNT(T10:W10) -> 4 | Z10: =R10*X10 -> 699.9 | AA10: 46086
A11: HB-4100422 | B11: 870774071458 | C11: ITM-700117 | D11: Nike, Inc. | E11: Nike | F11: Air Max Dn | G11: JK3828-236 | H11: Nike Air Max Dn "Black/Metallic Silver" Men's Shoe | I11: Casual | J11: Tech Running | K11: Men | L11: Black/Metallic Silver | M11: 13 | N11: D - Medium | O11: SU26 | P11: Active | Q11: 169.99 | R11: 169.99 | S11: 82.49 | V11: 4 | X11: =SUM(T11:W11) -> 4 | Y11: =COUNT(T11:W11) -> 1 | Z11: =R11*X11 -> 679.96 | AA11: 46048
A12: HB-4101174 | B12: 802956043183 | C12: ITM-700156 | D12: Nike, Inc. | E12: Nike | F12: Kobe 5 Protro | G12: MX1318-449 | H12: Nike Kobe 5 Protro "White/Varsity Purple" Men's Shoe | I12: Basketball | J12: Retro Performance | K12: Men | L12: White/Varsity Purple | M12: 10 | N12: D - Medium | O12: SU26 | P12: Active | Q12: 199.99 | R12: 199.99 | S12: 102.88 | T12: 5 | U12: 1 | V12: 5 | W12: 2 | X12: =SUM(T12:W12) -> 13 | Y12: =COUNT(T12:W12) -> 4 | Z12: =R12*X12 -> 2599.87 | AA12: 46101
A13: HB-4100490 | B13: 865594518943 | C13: ITM-700120 | D13: Nike, Inc. | E13: Nike | F13: Dunk Low | G13: YF5377-998 | H13: Nike Dunk Low "Midnight Navy/White" Big Kids' Shoe | I13: Casual | J13: Court / Lifestyle | K13: Big Kids | L13: Midnight Navy/White | M13: 4.5Y | N13: M - Medium | O13: HO25 | P13: Clearance | Q13: 94.99 | R13: 65.99 | S13: 47.59 | T13: 6 | V13: 4 | W13: 3 | X13: =SUM(T13:W13) -> 13 | Y13: =COUNT(T13:W13) -> 3 | Z13: =R13*X13 -> 857.87 | AA13: 46079
A14: HB-4102807 | B14: 837917925775 | C14: ITM-700230 | D14: New Balance Athletics, Inc. | E14: New Balance | F14: 9060 | G14: U1951JZR | H14: New Balance 9060 "Rain Cloud/Grey Matter" Men's Shoe | I14: Casual | J14: Retro Running | K14: Men | L14: Rain Cloud/Grey Matter | M14: 12 | N14: D - Medium | O14: HO25 | P14: Clearance | Q14: 149.99 | R14: 89.99 | S14: 74.84 | U14: 5 | V14: 3 | X14: =SUM(T14:W14) -> 8 | Y14: =COUNT(T14:W14) -> 2 | Z14: =R14*X14 -> 719.92 | AA14: 46155
A15: HB-4103772 | B15: 824165626004 | C15: ITM-700282 | D15: PUMA SE | E15: PUMA | F15: RS-X Efekt | G15: 832747-45 | H15: PUMA RS-X Efekt "White/Vapor Grey" Men's Shoe | I15: Casual | J15: Chunky Lifestyle | K15: Men | L15: White/Vapor Grey | M15: 11 | N15: D - Medium | O15: SU26 | P15: Active | Q15: 119.99 | R15: 119.99 | S15: 66.31 | T15: 4 | U15: 2 | V15: 4 | X15: =SUM(T15:W15) -> 10 | Y15: =COUNT(T15:W15) -> 3 | Z15: =R15*X15 -> 1199.9 | AA15: 46041
A16: HB-4101095 | B16: 888909252745 | C16: ITM-700153 | D16: Nike, Inc. | E16: Nike | F16: Giannis Immortality 4 | G16: RF7597-325 | H16: Nike Giannis Immortality 4 "Black/Green Strike" Big Kids' Shoe | I16: Basketball | J16: Signature | K16: Big Kids | L16: Black/Green Strike | M16: 4.5Y | N16: M - Medium | O16: SU26 | P16: Active | Q16: 84.99 | R16: 84.99 | S16: 46.96 | T16: 0 | U16: 3 | X16: =SUM(T16:W16) -> 3 | Y16: =COUNT(T16:W16) -> 2 | Z16: =R16*X16 -> 254.97 | AA16: 46080
A17: HB-4100541 | B17: 812477168963 | C17: ITM-700122 | D17: Nike, Inc. | E17: Nike | F17: Court Vision Low Next Nature | G17: CC5588-537 | H17: Nike Court Vision Low Next Nature "White/Black" Men's Shoe | I17: Casual | J17: Court / Lifestyle | K17: Men | L17: White/Black | M17: 9.5 | N17: D - Medium | O17: SU26 | P17: Active | Q17: 79.99 | R17: 79.99 | S17: 42.84 | T17: 2 | U17: 1 | V17: 4 | W17: 0 | X17: =SUM(T17:W17) -> 7 | Y17: =COUNT(T17:W17) -> 4 | Z17: =R17*X17 -> 559.93 | AA17: 46147
A18: HB-4102359 | B18: 864084016085 | C18: ITM-700214 | D18: adidas AG | E18: adidas | F18: Ultraboost 5 | G18: BJ7996 | H18: adidas Ultraboost 5 "Core Black/Carbon" Men's Shoe | I18: Running | J18: Neutral Cushion | K18: Men | L18: Core Black/Carbon | M18: 11 | N18: D - Medium | O18: SU26 | P18: Active | Q18: 189.99 | R18: 189.99 | S18: 103.72 | T18: 3 | U18: 1 | V18: 5 | X18: =SUM(T18:W18) -> 9 | Y18: =COUNT(T18:W18) -> 3 | Z18: =R18*X18 -> 1709.91 | AA18: 46168
A19: HB-4101362 | B19: 847434231972 | C19: ITM-700165 | D19: Nike, Inc. | E19: Jordan | F19: Air Jordan 1 Low | G19: TV5434-986 | H19: Jordan Air Jordan 1 Low "White/Sail/Pink" Women's Shoe | I19: Casual | J19: Retro Basketball | K19: Women | L19: White/Sail/Pink | M19: 7.5 | N19: B - Medium | O19: SU26 | P19: Clearance | Q19: 129.99 | R19: 77.99 | S19: 70.91 | V19: 0 | X19: =SUM(T19:W19) -> 0 | Y19: =COUNT(T19:W19) -> 1 | Z19: =R19*X19 -> 0 | AA19: 46133
A20: HB-4103833 | B20: 847077718461 | C20: ITM-700285 | D20: PUMA SE | E20: PUMA | F20: Softride Enzo Evo | G20: 355908-86 | H20: PUMA Softride Enzo Evo "Black/Cool Dark Grey" Men's Shoe | I20: Running | J20: Walking | K20: Men | L20: Black/Cool Dark Grey | M20: 10 | N20: D - Medium | O20: SU26 | P20: Active | Q20: 79.99 | R20: 79.99 | S20: 41.96 | T20: 3 | V20: 5 | W20: 1 | X20: =SUM(T20:W20) -> 9 | Y20: =COUNT(T20:W20) -> 3 | Z20: =R20*X20 -> 719.91 | AA20: 46228
A21: HB-4100877 | B21: 848475416799 | C21: ITM-700145 | D21: Nike, Inc. | E21: Nike | F21: InfinityRN 4 | G21: NT6349-799 | H21: Nike InfinityRN 4 "Barely Grape/Lilac" Women's Shoe | I21: Running | J21: Stability | K21: Women | L21: Barely Grape/Lilac | M21: 6.5 | N21: B - Medium | O21: SU26 | P21: Active | Q21: 164.99 | R21: 164.99 | S21: 89.57 | T21: 0 | U21: 0 | V21: 4 | W21: 2 | X21: =SUM(T21:W21) -> 6 | Y21: =COUNT(T21:W21) -> 4 | Z21: =R21*X21 -> 989.94 | AA21: 46060
A22: HB-4103817 | B22: 859579594457 | C22: ITM-700285 | D22: PUMA SE | E22: PUMA | F22: Softride Enzo Evo | G22: 355908-86 | H22: PUMA Softride Enzo Evo "Black/Cool Dark Grey" Men's Shoe | I22: Running | J22: Walking | K22: Men | L22: Black/Cool Dark Grey | M22: 8.5 | N22: D - Medium | O22: SU26 | P22: Active | Q22: 79.99 | R22: 79.99 | S22: 41.96 | T22: 4 | V22: 5 | W22: 1 | X22: =SUM(T22:W22) -> 10 | Y22: =COUNT(T22:W22) -> 3 | Z22: =R22*X22 -> 799.9 | AA22: 46168
A23: HB-4103401 | B23: 837235737479 | C23: ITM-700267 | D23: Under Armour, Inc. | E23: Under Armour | F23: Curry 12 | G23: 3029154-866 | H23: Under Armour Curry 12 "White/Team Royal" Men's Shoe | I23: Basketball | J23: Signature | K23: Men | L23: White/Team Royal | M23: 10 | N23: D - Medium | O23: SU26 | P23: Active | Q23: 169.99 | R23: 169.99 | S23: 86.49 | T23: 0 | U23: 3 | V23: 8 | X23: =SUM(T23:W23) -> 11 | Y23: =COUNT(T23:W23) -> 3 | Z23: =R23*X23 -> 1869.89 | AA23: 46199
A24: HB-4105636 | B24: 889723092906 | C24: ITM-700397 | D24: VF Corporation | E24: Timberland | F24: 6-Inch Premium Waterproof Boot | G24: TB0X6692R | H24: Timberland 6-Inch Premium Waterproof Boot "Wheat Nubuck" Men's Shoe | I24: Casual | J24: Boots | K24: Men | L24: Wheat Nubuck | M24: 10.5 | N24: D - Medium | O24: SP26 | P24: Active | Q24: 209.99 | R24: 209.99 | S24: 110.54 | T24: 5 | V24: 5 | X24: =SUM(T24:W24) -> 10 | Y24: =COUNT(T24:W24) -> 2 | Z24: =R24*X24 -> 2099.9 | AA24: 46037
A25: HB-4104520 | B25: 897745277299 | C25: ITM-700334 | D25: On Holding AG | E25: On | F25: Cloudnova 2 | G25: 307R23993 | H25: On Cloudnova 2 "White/Pearl" Women's Shoe | I25: Casual | J25: Tech Lifestyle | K25: Women | L25: White/Pearl | M25: 7 | N25: B - Medium | O25: SU26 | P25: Active | Q25: 159.99 | R25: 159.99 | S25: 87.47 | T25: 5 | U25: 4 | V25: 7 | X25: =SUM(T25:W25) -> 16 | Y25: =COUNT(T25:W25) -> 3 | Z25: =R25*X25 -> 2559.84 | AA25: 46166
A26: HB-4104364 | B26: 876101334564 | C26: ITM-700317 | D26: Deckers Brands | E26: HOKA | F26: Clifton 10 | G26: 1120932-NARX | H26: HOKA Clifton 10 "Black/White" Men's Shoe | I26: Running | J26: Premium Cushion | K26: Men | L26: Black/White | M26: 10 | N26: D - Medium | O26: SP26 | P26: Active | Q26: 154.99 | R26: 154.99 | S26: 78.28 | T26: 3 | U26: 4 | V26: 3 | W26: 0 | X26: =SUM(T26:W26) -> 10 | Y26: =COUNT(T26:W26) -> 4 | Z26: =R26*X26 -> 1549.9 | AA26: 46185
A27: HB-4104490 | B27: 828913028609 | C27: ITM-700326 | D27: Deckers Brands | E27: HOKA | F27: Arahi 8 | G27: 1150732-UCNK | H27: HOKA Arahi 8 "White/Coastal Sky" Women's Shoe | I27: Running | J27: Stability | K27: Women | L27: White/Coastal Sky | M27: 8 | N27: B - Medium | O27: SU26 | P27: Active | Q27: 154.99 | R27: 154.99 | S27: 85.1 | T27: 0 | U27: 3 | V27: 5 | X27: =SUM(T27:W27) -> 8 | Y27: =COUNT(T27:W27) -> 3 | Z27: =R27*X27 -> 1239.92 | AA27: 46167
A28: HB-4103743 | B28: 854961993890 | C28: ITM-700282 | D28: PUMA SE | E28: PUMA | F28: RS-X Efekt | G28: 832747-45 | H28: PUMA RS-X Efekt "White/Vapor Grey" Men's Shoe | I28: Casual | J28: Chunky Lifestyle | K28: Men | L28: White/Vapor Grey | M28: 10 | N28: D - Medium | O28: SU26 | P28: Active | Q28: 119.99 | R28: 119.99 | S28: 66.31 | T28: 1 | U28: 3 | V28: 5 | X28: =SUM(T28:W28) -> 9 | Y28: =COUNT(T28:W28) -> 3 | Z28: =R28*X28 -> 1079.91 | AA28: 46157
A29: HB-4101369 | B29: 882819340864 | C29: ITM-700165 | D29: Nike, Inc. | E29: Jordan | F29: Air Jordan 1 Low | G29: TV5434-986 | H29: Jordan Air Jordan 1 Low "White/Sail/Pink" Women's Shoe | I29: Casual | J29: Retro Basketball | K29: Women | L29: White/Sail/Pink | M29: 8 | N29: B - Medium | O29: SU26 | P29: Clearance | Q29: 129.99 | R29: 77.99 | S29: 70.91 | V29: 2 | X29: =SUM(T29:W29) -> 2 | Y29: =COUNT(T29:W29) -> 1 | Z29: =R29*X29 -> 155.98 | AA29: 46119
A30: HB-4100524 | B30: 808900209963 | C30: ITM-700120 | D30: Nike, Inc. | E30: Nike | F30: Dunk Low | G30: YF5377-998 | H30: Nike Dunk Low "Midnight Navy/White" Big Kids' Shoe | I30: Casual | J30: Court / Lifestyle | K30: Big Kids | L30: Midnight Navy/White | M30: 5.5Y | N30: M - Medium | O30: HO25 | P30: Clearance | Q30: 94.99 | R30: 65.99 | S30: 47.59 | T30: 2 | V30: 6 | W30: 0 | X30: =SUM(T30:W30) -> 8 | Y30: =COUNT(T30:W30) -> 3 | Z30: =R30*X30 -> 527.92 | AA30: 46224
A31: HB-4103610 | B31: 867246015740 | C31: ITM-700276 | D31: PUMA SE | E31: PUMA | F31: Palermo | G31: 848787-69 | H31: PUMA Palermo "Vapor Grey/Green" Women's Shoe | I31: Casual | J31: Terrace / Lifestyle | K31: Women | L31: Vapor Grey/Green | M31: 7 | N31: B - Medium | O31: FA26 | P31: Active | Q31: 89.99 | R31: 89.99 | S31: 45.15 | T31: 0 | V31: 4 | W31: 0 | X31: =SUM(T31:W31) -> 4 | Y31: =COUNT(T31:W31) -> 3 | Z31: =R31*X31 -> 359.96 | AA31: 46054
A32: HB-4105212 | B32: 870908185389 | C32: ITM-700375 | D32: Reebok International Ltd. | E32: Reebok | F32: Club C 85 | G32: 100029592 | H32: Reebok Club C 85 "White/Green" Men's Shoe | I32: Casual | J32: Court / Lifestyle | K32: Men | L32: White/Green | M32: 9.5 | N32: D - Medium | O32: FA25 | P32: Clearance | Q32: 89.99 | R32: 62.99 | S32: 49.53 | T32: 3 | U32: 2 | V32: 2 | W32: 4 | X32: =SUM(T32:W32) -> 11 | Y32: =COUNT(T32:W32) -> 4 | Z32: =R32*X32 -> 692.89 | AA32: 46226
A33: HB-4103021 | B33: 889320250523 | C33: ITM-700240 | D33: New Balance Athletics, Inc. | E33: New Balance | F33: Fresh Foam X 880v15 | G33: M0214WXX | H33: New Balance Fresh Foam X 880v15 "Black/Lead" Men's Shoe | I33: Running | J33: Neutral Cushion | K33: Men | L33: Black/Lead | M33: 12 | N33: D - Medium | O33: FA26 | P33: Pre-Season | Q33: 149.99 | R33: 149.99 | S33: 72.91 | T33: 5 | U33: 0 | V33: 6 | X33: =SUM(T33:W33) -> 11 | Y33: =COUNT(T33:W33) -> 3 | Z33: =R33*X33 -> 1649.89 | AA33: 46122
A34: HB-4102908 | B34: 865619966345 | C34: ITM-700237 | D34: New Balance Athletics, Inc. | E34: New Balance | F34: 480 | G34: W9114PEW | H34: New Balance 480 "White/Black" Big Kids' Shoe | I34: Casual | J34: Court / Lifestyle | K34: Big Kids | L34: White/Black | M34: 4.5Y | N34: M - Medium | O34: SU26 | P34: Active | Q34: 69.99 | R34: 69.99 | S34: 39.11 | T34: 4 | V34: 5 | X34: =SUM(T34:W34) -> 9 | Y34: =COUNT(T34:W34) -> 2 | Z34: =R34*X34 -> 629.91 | AA34: 46216
A35: HB-4102324 | B35: 839105167645 | C35: ITM-700210 | D35: adidas AG | E35: adidas | F35: Grand Court 2.0 | G35: XZ7710 | H35: adidas Grand Court 2.0 "Cloud White/Pink" Little Kids' Shoe | I35: Casual | J35: Court / Lifestyle | K35: Little Kids | L35: Cloud White/Pink | M35: 3Y | N35: M - Medium | O35: SU26 | P35: Active | Q35: 49.99 | R35: 49.99 | S35: 24.93 | T35: 0 | U35: 0 | V35: 3 | W35: 4 | X35: =SUM(T35:W35) -> 7 | Y35: =COUNT(T35:W35) -> 4 | Z35: =R35*X35 -> 349.93 | AA35: 46120
A36: HB-4104724 | B36: 866164912602 | C36: ITM-700347 | D36: Mizuno Corporation | E36: Mizuno | F36: Wave Rider 29 | G36: 616964-5195 | H36: Mizuno Wave Rider 29 "Black/Silver" Men's Shoe | I36: Running | J36: Neutral Cushion | K36: Men | L36: Black/Silver | M36: 9.5 | N36: D - Medium | O36: SP26 | P36: Active | Q36: 144.99 | R36: 144.99 | S36: 76.41 | T36: 1 | V36: 1 | X36: =SUM(T36:W36) -> 2 | Y36: =COUNT(T36:W36) -> 2 | Z36: =R36*X36 -> 289.98 | AA36: 46175
A37: HB-4103090 | B37: 807411451217 | C37: ITM-700247 | D37: New Balance Athletics, Inc. | E37: New Balance | F37: Fresh Foam Arishi v4 | G37: W8600KRG | H37: New Balance Fresh Foam Arishi v4 "Black/Silver" Men's Shoe | I37: Running | J37: Entry Cushion | K37: Men | L37: Black/Silver | M37: 10.5 | N37: D - Medium | O37: FA26 | P37: Active | Q37: 79.99 | R37: 79.99 | S37: 39.84 | T37: 5 | V37: 4 | X37: =SUM(T37:W37) -> 9 | Y37: =COUNT(T37:W37) -> 2 | Z37: =R37*X37 -> 719.91 | AA37: 46161
A38: HB-4102684 | B38: 819754951796 | C38: ITM-700227 | D38: New Balance Athletics, Inc. | E38: New Balance | F38: 574 Core | G38: M2807JKW | H38: New Balance 574 Core "Grey/White" Men's Shoe | I38: Casual | J38: Retro Running | K38: Men | L38: Grey/White | M38: 10 | N38: D - Medium | O38: HO25 | P38: Clearance | Q38: 89.99 | R38: 53.99 | S38: 46.24 | T38: 4 | U38: 2 | V38: 3 | W38: 1 | X38: =SUM(T38:W38) -> 10 | Y38: =COUNT(T38:W38) -> 4 | Z38: =R38*X38 -> 539.9 | AA38: 46218
A39: HB-4100045 | B39: 882027918718 | C39: ITM-700104 | D39: Nike, Inc. | E39: Nike | F39: Air Force 1 '07 | G39: ZT6343-223 | H39: Nike Air Force 1 '07 "White/White" Men's Shoe | I39: Casual | J39: Court / Lifestyle | K39: Men | L39: White/White | M39: 9.5 | N39: D - Medium | O39: SP26 | P39: Active | Q39: 124.99 | R39: 124.99 | S39: 68.25 | T39: 1 | U39: 1 | V39: 5 | X39: =SUM(T39:W39) -> 7 | Y39: =COUNT(T39:W39) -> 3 | Z39: =R39*X39 -> 874.93 | AA39: 46126
A40: HB-4105384 | B40: 871010395227 | C40: ITM-700385 | D40: Skechers U.S.A., Inc. | E40: Skechers | F40: Arch Fit 2.0 | G40: 215286-HPF | H40: Skechers Arch Fit 2.0 "Grey/Navy" Men's Shoe | I40: Running | J40: Walking | K40: Men | L40: Grey/Navy | M40: 11 | N40: D - Medium | O40: SU26 | P40: Active | Q40: 99.99 | R40: 99.99 | S40: 55.37 | T40: 3 | V40: 2 | W40: 4 | X40: =SUM(T40:W40) -> 9 | Y40: =COUNT(T40:W40) -> 3 | Z40: =R40*X40 -> 899.91 | AA40: 46103
...

Sheet Backroom Shelving 0146
A1: SKU | B1: UPC | C1: Item ID | D1: Brand | E1: Model | F1: Product Description | G1: Size | H1: On Hand - Store 0146 | I1: Sales Floor Units | J1: Back Room Units | K1: Stock Status | L1: Zone | M1: Zone Description | N1: Bay | O1: Shelf Level | P1: Bin | Q1: Location ID | R1: Shelf Label | S1: Shelf Height / Reach | T1: Overstock Location | U1: Pick Sequence | V1: Last Counted | W1: Suggested Agent Response
A2: HB-4104042 | B2: 818474894825 | C2: ITM-700298 | D2: ASICS | E2: GEL-EXCITE 11 | F2: ASICS GEL-EXCITE 11 "Black/Carrier Grey" Men's Shoe | G2: 9.5 | H2: =IFERROR(INDEX('Inventory Master'!$T$2:$T$525,MATCH($A2,'Inventory Master'!$A$2:$A$525,0)),0) -> 5 | I2: 0 | J2: =MAX(0,$H2-$I2) -> 5 | K2: =IF($H2>0,"In Stock","Out of Stock") -> In Stock | L2: A | M2: Men's Running & Training | N2: 1 | O2: 1 | P2: 1 | Q2: =$L2&"-"&TEXT($N2,"00")&"-"&$O2&"-"&TEXT($P2,"00") -> A-01-1-01 | R2: ="ZONE "&$L2&" / BAY "&TEXT($N2,"00")&" / SHELF "&$O2&" / BIN "&TEXT($P2,"00") -> ZONE A / BAY 01 / SHELF 1 / BIN 01 | S2: Floor level - no reach | T2: n/a | U2: 1 | V2: 46145 | W2: =IF($H2>0,"Yes - "&$H2&" in stock at Store 0146 (size "&$G2&"). Back room location "&$Q2&" ("&$R2&"), "&$S2&". Back room "&$J2&" / sales floor "&$I2&".","Not currently in stock at Store 0146 (size "&$G2&"). Home location is "&$Q2&" ("&$R2&") when replenished.") -> Yes - 5 in stock at Store 0146 (size 9.5). Back room location A-01-1-01 (ZONE A / BAY 01 / SHELF 1 / BIN 01), Floor level - no reach. Back room 5 / sales floor 0.
A3: HB-4104054 | B3: 855904345660 | C3: ITM-700298 | D3: ASICS | E3: GEL-EXCITE 11 | F3: ASICS GEL-EXCITE 11 "Black/Carrier Grey" Men's Shoe | G3: 10 | H3: =IFERROR(INDEX('Inventory Master'!$T$2:$T$525,MATCH($A3,'Inventory Master'!$A$2:$A$525,0)),0) -> 3 | I3: 2 | J3: =MAX(0,$H3-$I3) -> 1 | K3: =IF($H3>0,"In Stock","Out of Stock") -> In Stock | L3: A | M3: Men's Running & Training | N3: 1 | O3: 1 | P3: 2 | Q3: =$L3&"-"&TEXT($N3,"00")&"-"&$O3&"-"&TEXT($P3,"00") -> A-01-1-02 | R3: ="ZONE "&$L3&" / BAY "&TEXT($N3,"00")&" / SHELF "&$O3&" / BIN "&TEXT($P3,"00") -> ZONE A / BAY 01 / SHELF 1 / BIN 02 | S3: Floor level - no reach | T3: n/a | U3: 2 | V3: 46179 | W3: =IF($H3>0,"Yes - "&$H3&" in stock at Store 0146 (size "&$G3&"). Back room location "&$Q3&" ("&$R3&"), "&$S3&". Back room "&$J3&" / sales floor "&$I3&".","Not currently in stock at Store 0146 (size "&$G3&"). Home location is "&$Q3&" ("&$R3&") when replenished.") -> Yes - 3 in stock at Store 0146 (size 10). Back room location A-01-1-02 (ZONE A / BAY 01 / SHELF 1 / BIN 02), Floor level - no reach. Back room 1 / sales floor 2.
A4: HB-4104069 | B4: 811895179780 | C4: ITM-700298 | D4: ASICS | E4: GEL-EXCITE 11 | F4: ASICS GEL-EXCITE 11 "Black/Carrier Grey" Men's Shoe | G4: 10.5 | H4: =IFERROR(INDEX('Inventory Master'!$T$2:$T$525,MATCH($A4,'Inventory Master'!$A$2:$A$525,0)),0) -> 0 | I4: 0 | J4: =MAX(0,$H4-$I4) -> 0 | K4: =IF($H4>0,"In Stock","Out of Stock") -> Out of Stock | L4: A | M4: Men's Running & Training | N4: 1 | O4: 1 | P4: 3 | Q4: =$L4&"-"&TEXT($N4,"00")&"-"&$O4&"-"&TEXT($P4,"00") -> A-01-1-03 | R4: ="ZONE "&$L4&" / BAY "&TEXT($N4,"00")&" / SHELF "&$O4&" / BIN "&TEXT($P4,"00") -> ZONE A / BAY 01 / SHELF 1 / BIN 03 | S4: Floor level - no reach | T4: n/a | U4: 3 | V4: 46160 | W4: =IF($H4>0,"Yes - "&$H4&" in stock at Store 0146 (size "&$G4&"). Back room location "&$Q4&" ("&$R4&"), "&$S4&". Back room "&$J4&" / sales floor "&$I4&".","Not currently in stock at Store 0146 (size "&$G4&"). Home location is "&$Q4&" ("&$R4&") when replenished.") -> Not currently in stock at Store 0146 (size 10.5). Home location is A-01-1-03 (ZONE A / BAY 01 / SHELF 1 / BIN 03) when replenished.
A5: HB-4104088 | B5: 848629257426 | C5: ITM-700298 | D5: ASICS | E5: GEL-EXCITE 11 | F5: ASICS GEL-EXCITE 11 "Black/Carrier Grey" Men's Shoe | G5: 11 | H5: =IFERROR(INDEX('Inventory Master'!$T$2:$T$525,MATCH($A5,'Inventory Master'!$A$2:$A$525,0)),0) -> 2 | I5: 0 | J5: =MAX(0,$H5-$I5) -> 2 | K5: =IF($H5>0,"In Stock","Out of Stock") -> In Stock | L5: A | M5: Men's Running & Training | N5: 1 | O5: 1 | P5: 4 | Q5: =$L5&"-"&TEXT($N5,"00")&"-"&$O5&"-"&TEXT($P5,"00") -> A-01-1-04 | R5: ="ZONE "&$L5&" / BAY "&TEXT($N5,"00")&" / SHELF "&$O5&" / BIN "&TEXT($P5,"00") -> ZONE A / BAY 01 / SHELF 1 / BIN 04 | S5: Floor level - no reach | T5: n/a | U5: 4 | V5: 46221 | W5: =IF($H5>0,"Yes - "&$H5&" in stock at Store 0146 (size "&$G5&"). Back room location "&$Q5&" ("&$R5&"), "&$S5&". Back room "&$J5&" / sales floor "&$I5&".","Not currently in stock at Store 0146 (size "&$G5&"). Home location is "&$Q5&" ("&$R5&") when replenished.") -> Yes - 2 in stock at Store 0146 (size 11). Back room location A-01-1-04 (ZONE A / BAY 01 / SHELF 1 / BIN 04), Floor level - no reach. Back room 2 / sales floor 0.
A6: HB-4104096 | B6: 882194120494 | C6: ITM-700298 | D6: ASICS | E6: GEL-EXCITE 11 | F6: ASICS GEL-EXCITE 11 "Black/Carrier Grey" Men's Shoe | G6: 11.5 | H6: =IFERROR(INDEX('Inventory Master'!$T$2:$T$525,MATCH($A6,'Inventory Master'!$A$2:$A$525,0)),0) -> 0 | I6: 0 | J6: =MAX(0,$H6-$I6) -> 0 | K6: =IF($H6>0,"In Stock","Out of Stock") -> Out of Stock | L6: A | M6: Men's Running & Training | N6: 1 | O6: 1 | P6: 5 | Q6: =$L6&"-"&TEXT($N6,"00")&"-"&$O6&"-"&TEXT($P6,"00") -> A-01-1-05 | R6: ="ZONE "&$L6&" / BAY "&TEXT($N6,"00")&" / SHELF "&$O6&" / BIN "&TEXT($P6,"00") -> ZONE A / BAY 01 / SHELF 1 / BIN 05 | S6: Floor level - no reach | T6: n/a | U6: 5 | V6: 46176 | W6: =IF($H6>0,"Yes - "&$H6&" in stock at Store 0146 (size "&$G6&"). Back room location "&$Q6&" ("&$R6&"), "&$S6&". Back room "&$J6&" / sales floor "&$I6&".","Not currently in stock at Store 0146 (size "&$G6&"). Home location is "&$Q6&" ("&$R6&") when replenished.") -> Not currently in stock at Store 0146 (size 11.5). Home location is A-01-1-05 (ZONE A / BAY 01 / SHELF 1 / BIN 05) when replenished.
A7: HB-4104203 | B7: 876458462134 | C7: ITM-700306 | D7: Brooks | E7: Ghost 17 | F7: Brooks Ghost 17 "Black/Ebony/Grey" Men's Shoe | G7: 8 | H7: =IFERROR(INDEX('Inventory Master'!$T$2:$T$525,MATCH($A7,'Inventory Master'!$A$2:$A$525,0)),0) -> 1 | I7: 1 | J7: =MAX(0,$H7-$I7) -> 0 | K7: =IF($H7>0,"In Stock","Out of Stock") -> In Stock | L7: A | M7: Men's Running & Training | N7: 1 | O7: 2 | P7: 1 | Q7: =$L7&"-"&TEXT($N7,"00")&"-"&$O7&"-"&TEXT($P7,"00") -> A-01-2-01 | R7: ="ZONE "&$L7&" / BAY "&TEXT($N7,"00")&" / SHELF "&$O7&" / BIN "&TEXT($P7,"00") -> ZONE A / BAY 01 / SHELF 2 / BIN 01 | S7: Waist height | T7: n/a | U7: 6 | V7: 46141 | W7: =IF($H7>0,"Yes - "&$H7&" in stock at Store 0146 (size "&$G7&"). Back room location "&$Q7&" ("&$R7&"), "&$S7&". Back room "&$J7&" / sales floor "&$I7&".","Not currently in stock at Store 0146 (size "&$G7&"). Home location is "&$Q7&" ("&$R7&") when replenished.") -> Yes - 1 in stock at Store 0146 (size 8). Back room location A-01-2-01 (ZONE A / BAY 01 / SHELF 2 / BIN 01), Waist height. Back room 0 / sales floor 1.
A8: HB-4104206 | B8: 859477541235 | C8: ITM-700306 | D8: Brooks | E8: Ghost 17 | F8: Brooks Ghost 17 "Black/Ebony/Grey" Men's Shoe | G8: 8.5 | H8: =IFERROR(INDEX('Inventory Master'!$T$2:$T$525,MATCH($A8,'Inventory Master'!$A$2:$A$525,0)),0) -> 4 | I8: 2 | J8: =MAX(0,$H8-$I8) -> 2 | K8: =IF($H8>0,"In Stock","Out of Stock") -> In Stock | L8: A | M8: Men's Running & Training | N8: 1 | O8: 2 | P8: 2 | Q8: =$L8&"-"&TEXT($N8,"00")&"-"&$O8&"-"&TEXT($P8,"00") -> A-01-2-02 | R8: ="ZONE "&$L8&" / BAY "&TEXT($N8,"00")&" / SHELF "&$O8&" / BIN "&TEXT($P8,"00") -> ZONE A / BAY 01 / SHELF 2 / BIN 02 | S8: Waist height | T8: n/a | U8: 7 | V8: 46198 | W8: =IF($H8>0,"Yes - "&$H8&" in stock at Store 0146 (size "&$G8&"). Back room location "&$Q8&" ("&$R8&"), "&$S8&". Back room "&$J8&" / sales floor "&$I8&".","Not currently in stock at Store 0146 (size "&$G8&"). Home location is "&$Q8&" ("&$R8&") when replenished.") -> Yes - 4 in stock at Store 0146 (size 8.5). Back room location A-01-2-02 (ZONE A / BAY 01 / SHELF 2 / BIN 02), Waist height. Back room 2 / sales floor 2.
A9: HB-4104220 | B9: 801963824529 | C9: ITM-700306 | D9: Brooks | E9: Ghost 17 | F9: Brooks Ghost 17 "Black/Ebony/Grey" Men's Shoe | G9: 9 | H9: =IFERROR(INDEX('Inventory Master'!$T$2:$T$525,MATCH($A9,'Inventory Master'!$A$2:$A$525,0)),0) -> 4 | I9: 1 | J9: =MAX(0,$H9-$I9) -> 3 | K9: =IF($H9>0,"In Stock","Out of Stock") -> In Stock | L9: A | M9: Men's Running & Training | N9: 1 | O9: 2 | P9: 3 | Q9: =$L9&"-"&TEXT($N9,"00")&"-"&$O9&"-"&TEXT($P9,"00") -> A-01-2-03 | R9: ="ZONE "&$L9&" / BAY "&TEXT($N9,"00")&" / SHELF "&$O9&" / BIN "&TEXT($P9,"00") -> ZONE A / BAY 01 / SHELF 2 / BIN 03 | S9: Waist height | T9: n/a | U9: 8 | V9: 46206 | W9: =IF($H9>0,"Yes - "&$H9&" in stock at Store 0146 (size "&$G9&"). Back room location "&$Q9&" ("&$R9&"), "&$S9&". Back room "&$J9&" / sales floor "&$I9&".","Not currently in stock at Store 0146 (size "&$G9&"). Home location is "&$Q9&" ("&$R9&") when replenished.") -> Yes - 4 in stock at Store 0146 (size 9). Back room location A-01-2-03 (ZONE A / BAY 01 / SHELF 2 / BIN 03), Waist height. Back room 3 / sales floor 1.
A10: HB-4104292 | B10: 896826526176 | C10: ITM-700316 | D10: Brooks | E10: Glycerin 22 | F10: Brooks Glycerin 22 "Grey/Navy/Blue" Men's Shoe | G10: 8.5 | H10: =IFERROR(INDEX('Inventory Master'!$T$2:$T$525,MATCH($A10,'Inventory Master'!$A$2:$A$525,0)),0) -> 2 | I10: 1 | J10: =MAX(0,$H10-$I10) -> 1 | K10: =IF($H10>0,"In Stock","Out of Stock") -> In Stock | L10: A | M10: Men's Running & Training | N10: 1 | O10: 3 | P10: 1 | Q10: =$L10&"-"&TEXT($N10,"00")&"-"&$O10&"-"&TEXT($P10,"00") -> A-01-3-01 | R10: ="ZONE "&$L10&" / BAY "&TEXT($N10,"00")&" / SHELF "&$O10&" / BIN "&TEXT($P10,"00") -> ZONE A / BAY 01 / SHELF 3 / BIN 01 | S10: Eye level | T10: n/a | U10: 9 | V10: 46204 | W10: =IF($H10>0,"Yes - "&$H10&" in stock at Store 0146 (size "&$G10&"). Back room location "&$Q10&" ("&$R10&"), "&$S10&". Back room "&$J10&" / sales floor "&$I10&".","Not currently in stock at Store 0146 (size "&$G10&"). Home location is "&$Q10&" ("&$R10&") when replenished.") -> Yes - 2 in stock at Store 0146 (size 8.5). Back room location A-01-3-01 (ZONE A / BAY 01 / SHELF 3 / BIN 01), Eye level. Back room 1 / sales floor 1.
A11: HB-4104298 | B11: 843556313047 | C11: ITM-700316 | D11: Brooks | E11: Glycerin 22 | F11: Brooks Glycerin 22 "Grey/Navy/Blue" Men's Shoe | G11: 9 | H11: =IFERROR(INDEX('Inventory Master'!$T$2:$T$525,MATCH($A11,'Inventory Master'!$A$2:$A$525,0)),0) -> 5 | I11: 2 | J11: =MAX(0,$H11-$I11) -> 3 | K11: =IF($H11>0,"In Stock","Out of Stock") -> In Stock | L11: A | M11: Men's Running & Training | N11: 1 | O11: 3 | P11: 2 | Q11: =$L11&"-"&TEXT($N11,"00")&"-"&$O11&"-"&TEXT($P11,"00") -> A-01-3-02 | R11: ="ZONE "&$L11&" / BAY "&TEXT($N11,"00")&" / SHELF "&$O11&" / BIN "&TEXT($P11,"00") -> ZONE A / BAY 01 / SHELF 3 / BIN 02 | S11: Eye level | T11: n/a | U11: 10 | V11: 46231 | W11: =IF($H11>0,"Yes - "&$H11&" in stock at Store 0146 (size "&$G11&"). Back room location "&$Q11&" ("&$R11&"), "&$S11&". Back room "&$J11&" / sales floor "&$I11&".","Not currently in stock at Store 0146 (size "&$G11&"). Home location is "&$Q11&" ("&$R11&") when replenished.") -> Yes - 5 in stock at Store 0146 (size 9). Back room location A-01-3-02 (ZONE A / BAY 01 / SHELF 3 / BIN 02), Eye level. Back room 3 / sales floor 2.
A12: HB-4104307 | B12: 826648843806 | C12: ITM-700316 | D12: Brooks | E12: Glycerin 22 | F12: Brooks Glycerin 22 "Grey/Navy/Blue" Men's Shoe | G12: 9.5 | H12: =IFERROR(INDEX('Inventory Master'!$T$2:$T$525,MATCH($A12,'Inventory Master'!$A$2:$A$525,0)),0) -> 0 | I12: 0 | J12: =MAX(0,$H12-$I12) -> 0 | K12: =IF($H12>0,"In Stock","Out of Stock") -> Out of Stock | L12: A | M12: Men's Running & Training | N12: 1 | O12: 3 | P12: 3 | Q12: =$L12&"-"&TEXT($N12,"00")&"-"&$O12&"-"&TEXT($P12,"00") -> A-01-3-03 | R12: ="ZONE "&$L12&" / BAY "&TEXT($N12,"00")&" / SHELF "&$O12&" / BIN "&TEXT($P12,"00") -> ZONE A / BAY 01 / SHELF 3 / BIN 03 | S12: Eye level | T12: n/a | U12: 11 | V12: 46205 | W12: =IF($H12>0,"Yes - "&$H12&" in stock at Store 0146 (size "&$G12&"). Back room location "&$Q12&" ("&$R12&"), "&$S12&". Back room "&$J12&" / sales floor "&$I12&".","Not currently in stock at Store 0146 (size "&$G12&"). Home location is "&$Q12&" ("&$R12&") when replenished.") -> Not currently in stock at Store 0146 (size 9.5). Home location is A-01-3-03 (ZONE A / BAY 01 / SHELF 3 / BIN 03) when replenished.
A13: HB-4104319 | B13: 853054309369 | C13: ITM-700316 | D13: Brooks | E13: Glycerin 22 | F13: Brooks Glycerin 22 "Grey/Navy/Blue" Men's Shoe | G13: 10 | H13: =IFERROR(INDEX('Inventory Master'!$T$2:$T$525,MATCH($A13,'Inventory Master'!$A$2:$A$525,0)),0) -> 3 | I13: 2 | J13: =MAX(0,$H13-$I13) -> 1 | K13: =IF($H13>0,"In Stock","Out of Stock") -> In Stock | L13: A | M13: Men's Running & Training | N13: 1 | O13: 3 | P13: 4 | Q13: =$L13&"-"&TEXT($N13,"00")&"-"&$O13&"-"&TEXT($P13,"00") -> A-01-3-04 | R13: ="ZONE "&$L13&" / BAY "&TEXT($N13,"00")&" / SHELF "&$O13&" / BIN "&TEXT($P13,"00") -> ZONE A / BAY 01 / SHELF 3 / BIN 04 | S13: Eye level | T13: n/a | U13: 12 | V13: 46211 | W13: =IF($H13>0,"Yes - "&$H13&" in stock at Store 0146 (size "&$G13&"). Back room location "&$Q13&" ("&$R13&"), "&$S13&". Back room "&$J13&" / sales floor "&$I13&".","Not currently in stock at Store 0146 (size "&$G13&"). Home location is "&$Q13&" ("&$R13&") when replenished.") -> Yes - 3 in stock at Store 0146 (size 10). Back room location A-01-3-04 (ZONE A / BAY 01 / SHELF 3 / BIN 04), Eye level. Back room 1 / sales floor 2.
... A444: HB-4102582 | B444: 877862873808 | C444: ITM-700225 | D444: adidas | E444: Adilette Comfort Slide | F444: adidas Adilette Comfort Slide "Core Black/White" Men's Shoe | G444: 13 | H444: =IFERROR(INDEX('Inventory Master'!$T$2:$T$525,MATCH($A444,'Inventory Master'!$A$2:$A$525,0)),0) -> 3 | I444: 2 | J444: =MAX(0,$H444-$I444) -> 1 | K444: =IF($H444>0,"In Stock","Out of Stock") -> In Stock | L444: F | M444: Sandals, Slides, Clogs & Boots | N444: 2 | O444: 2 | P444: 6 | Q444: =$L444&"-"&TEXT($N444,"00")&"-"&$O444&"-"&TEXT($P444,"00") -> F-02-2-06 | R444: ="ZONE "&$L444&" / BAY "&TEXT($N444,"00")&" / SHELF "&$O444&" / BIN "&TEXT($P444,"00") -> ZONE F / BAY 02 / SHELF 2 / BIN 06 | S444: Waist height | T444: n/a | U444: 443 | V444: 46218 | W444: =IF($H444>0,"Yes - "&$H444&" in stock at Store 0146 (size "&$G444&"). Back room location "&$Q444&" ("&$R444&"), "&$S444&". Back room "&$J444&" / sales floor "&$I444&".","Not currently in stock at Store 0146 (size "&$G444&"). Home location is "&$Q444&" ("&$R444&") when replenished.") -> Yes - 3 in stock at Store 0146 (size 13). Back room location F-02-2-06 (ZONE F / BAY 02 / SHELF 2 / BIN 06), Waist height. Back room 1 / sales floor 2.
A445: TOTAL | H445: =SUM(H2:H444) -> 1152 | I445: =SUM(I2:I444) -> 380 | J445: =SUM(J2:J444) -> 772 | K445: =COUNTIF(K2:K444,"In Stock")&" of "&443&" SKUs in stock" -> 354 of 443 SKUs in stock
A447: Location ID grammar: ZONE - BAY - SHELF - BIN (e.g. C-07-3-04 = Zone C, Bay 07, Shelf 3, Bin 04). Every size of a given style shares one shelf, running left to right in ascending size order, so a whole style can be pulled from a single shelf. Rows are sorted in pick-walk sequence.

Sheet Style Master
A1: Item ID | B1: Manufacturer | C1: Brand | D1: Model | E1: Style Number | F1: Product Description | G1: Category | H1: Sub-Category | I1: Gender | J1: Color | K1: Season | L1: Lifecycle Status | M1: MSRP | N1: Current Retail | O1: Unit Cost | P1: Assortment Tier | Q1: Stores Assorted | R1: SKUs (Sizes) | S1: Total Units On Hand | T1: On-Hand Retail Value
A2: ITM-700305 | B2: ASICS Corporation | C2: ASICS | D2: GEL-1130 | E2: 1091B332-674 | F2: ASICS GEL-1130 "White/Clay Canyon" Unisex Shoe | G2: Casual | H2: Retro Running | I2: Unisex | J2: White/Clay Canyon | K2: SP26 | L2: Clearance | M2: 109.99 | N2: 70.99 | O2: 57.65 | P2: B (3 of 4 stores) | Q2: 3 | R2: =COUNTIF('Inventory Master'!$C$2:$C$525,$A2) -> 3 | S2: =SUMIF('Inventory Master'!$C$2:$C$525,$A2,'Inventory Master'!$X$2:$X$525) -> 26 | T2: =SUMIF('Inventory Master'!$C$2:$C$525,$A2,'Inventory Master'!$Z$2:$Z$525) -> 1845.74
A3: ITM-700301 | B3: ASICS Corporation | C3: ASICS | D3: GEL-CONTEND 9 | E3: 1001B908-716 | F3: ASICS GEL-CONTEND 9 "White/Rose" Women's Shoe | G3: Running | H3: Entry Cushion | I3: Women | J3: White/Rose | K3: SP26 | L3: Clearance | M3: 69.99 | N3: 41.99 | O3: 36.27 | P3: D (1 of 4 stores) | Q3: 1 | R3: =COUNTIF('Inventory Master'!$C$2:$C$525,$A3) -> 4 | S3: =SUMIF('Inventory Master'!$C$2:$C$525,$A3,'Inventory Master'!$X$2:$X$525) -> 5 | T3: =SUMIF('Inventory Master'!$C$2:$C$525,$A3,'Inventory Master'!$Z$2:$Z$525) -> 209.95
A4: ITM-700298 | B4: ASICS Corporation | C4: ASICS | D4: GEL-EXCITE 11 | E4: 1069B692-193 | F4: ASICS GEL-EXCITE 11 "Black/Carrier Grey" Men's Shoe | G4: Running | H4: Entry Cushion | I4: Men | J4: Black/Carrier Grey | K4: SP26 | L4: Active | M4: 79.99 | N4: 79.99 | O4: 40.55 | P4: B (3 of 4 stores) | Q4: 3 | R4: =COUNTIF('Inventory Master'!$C$2:$C$525,$A4) -> 5 | S4: =SUMIF('Inventory Master'!$C$2:$C$525,$A4,'Inventory Master'!$X$2:$X$525) -> 40 | T4: =SUMIF('Inventory Master'!$C$2:$C$525,$A4,'Inventory Master'!$Z$2:$Z$525) -> 3199.6
A5: ITM-700293 | B5: ASICS Corporation | C5: ASICS | D5: GEL-KAYANO 32 | E5: 1061B874-346 | F5: ASICS GEL-KAYANO 32 "Black/Graphite Grey" Men's Shoe | G5: Running | H5: Stability | I5: Men | J5: Black/Graphite Grey | K5: FA25 | L5: Clearance | M5: 169.99 | N5: 101.99 | O5: 84.77 | P5: D (1 of 4 stores) | Q5: 1 | R5: =COUNTIF('Inventory Master'!$C$2:$C$525,$A5) -> 5 | S5: =SUMIF('Inventory Master'!$C$2:$C$525,$A5,'Inventory Master'!$X$2:$X$525) -> 16 | T5: =SUMIF('Inventory Master'!$C$2:$C$525,$A5,'Inventory Master'!$Z$2:$Z$525) -> 1631.84
A6: ITM-700294 | B6: ASICS Corporation | C6: ASICS | D6: GEL-NIMBUS 28 | E6: 1032B092-817 | F6: ASICS GEL-NIMBUS 28 "Cloud Grey/Sky" Women's Shoe | G6: Running | H6: Premium Cushion | I6: Women | J6: Cloud Grey/Sky | K6: SP26 | L6: Active | M6: 179.99 | N6: 179.99 | O6: 97.26 | P6: B (3 of 4 stores) | Q6: 3 | R6: =COUNTIF('Inventory Master'!$C$2:$C$525,$A6) -> 5 | S6: =SUMIF('Inventory Master'!$C$2:$C$525,$A6,'Inventory Master'!$X$2:$X$525) -> 35 | T6: =SUMIF('Inventory Master'!$C$2:$C$525,$A6,'Inventory Master'!$Z$2:$Z$525) -> 6299.65
A7: ITM-700302 | B7: ASICS Corporation | C7: ASICS | D7: GEL-NYC | E7: 1024B246-768 | F7: ASICS GEL-NYC "Oyster Grey/Clay Grey" Unisex Shoe | G7: Casual | H7: Retro Running | I7: Unisex | J7: Oyster Grey/Clay Grey | K7: SP26 | L7: Active | M7: 149.99 | N7: 149.99 | O7: 80.52 | P7: A (4 of 4 stores) | Q7: 4 | R7: =COUNTIF('Inventory Master'!$C$2:$C$525,$A7) -> 3 | S7: =SUMIF('Inventory Master'!$C$2:$C$525,$A7,'Inventory Master'!$X$2:$X$525) -> 31 | T7: =SUMIF('Inventory Master'!$C$2:$C$525,$A7,'Inventory Master'!$Z$2:$Z$525) -> 4649.69
A8: ITM-700402 | B8: Birkenstock GmbH | C8: Birkenstock | D8: Arizona Essentials EVA | E8: 4242715 | F8: Birkenstock Arizona Essentials EVA "Black" Unisex Shoe | G8: Sandals | H8: Sandals | I8: Unisex | J8: Black | K8: HO25 | L8: Active | M8: 54.99 | N8: 54.99 | O8: 26.61 | P8: C (2 of 4 stores) | Q8: 2 | R8: =COUNTIF('Inventory Master'!$C$2:$C$525,$A8) -> 6 | S8: =SUMIF('Inventory Master'!$C$2:$C$525,$A8,'Inventory Master'!$X$2:$X$525) -> 36 | T8: =SUMIF('Inventory Master'!$C$2:$C$525,$A8,'Inventory Master'!$Z$2:$Z$525) -> 1979.64
A9: ITM-700314 | B9: Brooks Sports, Inc. | C9: Brooks | D9: Adrenaline GTS 24 | E9: 110377-1D-913 | F9: Brooks Adrenaline GTS 24 "Grey/Lilac/Silver" Women's Shoe | G9: Running | H9: Stability | I9: Women | J9: Grey/Lilac/Silver | K9: SP26 | L9: Active | M9: 149.99 | N9: 149.99 | O9: 72.34 | P9: A (4 of 4 stores) | Q9: 4 | R9: =COUNTIF('Inventory Master'!$C$2:$C$525,$A9) -> 3 | S9: =SUMIF('Inventory Master'!$C$2:$C$525,$A9,'Inventory Master'!$X$2:$X$525) -> 30 | T9: =SUMIF('Inventory Master'!$C$2:$C$525,$A9,'Inventory Master'!$Z$2:$Z$525) -> 4499.7
A10: ITM-700306 | B10: Brooks Sports, Inc. | C10: Brooks | D10: Ghost 17 | E10: 110390-1D-470 | F10: Brooks Ghost 17 "Black/Ebony/Grey" Men's Shoe | G10: Running | H10: Neutral Cushion | I10: Men | J10: Black/Ebony/Grey | K10: FA25 | L10: Active | M10: 149.99 | N10: 149.99 | O10: 76.29 | P10: A (4 of 4 stores) | Q10: 4 | R10: =COUNTIF('Inventory Master'!$C$2:$C$525,$A10) -> 3 | S10: =SUMIF('Inventory Master'!$C$2:$C$525,$A10,'Inventory Master'!$X$2:$X$525) -> 30 | T10: =SUMIF('Inventory Master'!$C$2:$C$525,$A10,'Inventory Master'!$Z$2:$Z$525) -> 4499.7
A11: ITM-700310 | B11: Brooks Sports, Inc. | C11: Brooks | D11: Ghost 17 | E11: 110343-1D-175 | F11: Brooks Ghost 17 "White/Coral/Peach" Women's Shoe | G11: Running | H11: Neutral Cushion | I11: Women | J11: White/Coral/Peach | K11: FA26 | L11: Pre-Season | M11: 149.99 | N11: 149.99 | O11: 73.89 | P11: B (3 of 4 stores) | Q11: 3 | R11: =COUNTIF('Inventory Master'!$C$2:$C$525,$A11) -> 3 | S11: =SUMIF('Inventory Master'!$C$2:$C$525,$A11,'Inventory Master'!$X$2:$X$525) -> 31 | T11: =SUMIF('Inventory Master'!$C$2:$C$525,$A11,'Inventory Master'!$Z$2:$Z$525) -> 4649.69
A12: ITM-700316 | B12: Brooks Sports, Inc. | C12: Brooks | D12: Glycerin 22 | E12: 110320-1D-271 | F12: Brooks Glycerin 22 "Grey/Navy/Blue" Men's Shoe | G12: Running | H12: Premium Cushion | I12: Men | J12: Grey/Navy/Blue | K12: SU26 | L12: Active | M12: 169.99 | N12: 169.99 | O12: 89.36 | P12: C (2 of 4 stores) | Q12: 2 | R12: =COUNTIF('Inventory Master'!$C$2:$C$525,$A12) -> 6 | S12: =SUMIF('Inventory Master'!$C$2:$C$525,$A12,'Inventory Master'!$X$2:$X$525) -> 45 | T12: =SUMIF('Inventory Master'!$C$2:$C$525,$A12,'Inventory Master'!$Z$2:$Z$525) -> 7649.55
A13: ITM-700359 | B13: Converse, Inc. | C13: Converse | D13: Chuck 70 Low | E13: M9038V | F13: Converse Chuck 70 Low "Parchment/Egret" Unisex Shoe | G13: Casual | H13: Canvas / Skate | I13: Unisex | J13: Parchment/Egret | K13: SP26 | L13: Active | M13: 89.99 | N13: 89.99 | O13: 44.27 | P13: A (4 of 4 stores) | Q13: 4 | R13: =COUNTIF('Inventory Master'!$C$2:$C$525,$A13) -> 5 | S13: =SUMIF('Inventory Master'!$C$2:$C$525,$A13,'Inventory Master'!$X$2:$X$525) -> 46 | T13: =SUMIF('Inventory Master'!$C$2:$C$525,$A13,'Inventory Master'!$Z$2:$Z$525) -> 4139.54
... A119: ITM-700200 | B119: adidas AG | C119: adidas Originals | D119: Superstar | E119: UP8227 | F119: adidas Originals Superstar "White/Core Black" Big Kids' Shoe | G119: Casual | H119: Court / Lifestyle | I119: Big Kids | J119: White/Core Black | K119: FA26 | L119: Active | M119: 74.99 | N119: 74.99 | O119: 39.21 | P119: A (4 of 4 stores) | Q119: 4 | R119: =COUNTIF('Inventory Master'!$C$2:$C$525,$A119) -> 5 | S119: =SUMIF('Inventory Master'!$C$2:$C$525,$A119,'Inventory Master'!$X$2:$X$525) -> 58 | T119: =SUMIF('Inventory Master'!$C$2:$C$525,$A119,'Inventory Master'!$Z$2:$Z$525) -> 4349.42
A120: TOTAL | R120: =SUM(R2:R119) -> 524 | S120: =SUM(S2:S119) -> 4021 | T120: =SUM(T2:T119) -> 446453.79

Sheet Store Summary
A1: Store Summary — Units On Hand
A2: Live SUMIFS against Inventory Master. Filtering Inventory Master does not change these figures.
A4: Units On Hand by Brand
A5: Brand | B5: Store 0146 | C5: Store 1382 | D5: Store 2071 | E5: Store 3719 | F5: All Stores | G5: % of Chain
A6: ASICS | B6: =SUMIF('Inventory Master'!$E$2:$E$525,$A6,'Inventory Master'!$T$2:$T$525) -> 37 | C6: =SUMIF('Inventory Master'!$E$2:$E$525,$A6,'Inventory Master'!$U$2:$U$525) -> 27 | D6: =SUMIF('Inventory Master'!$E$2:$E$525,$A6,'Inventory Master'!$V$2:$V$525) -> 75 | E6: =SUMIF('Inventory Master'!$E$2:$E$525,$A6,'Inventory Master'!$W$2:$W$525) -> 14 | F6: =SUM(B6:E6) -> 153 | G6: =IFERROR(F6/F$28,0) -> 0.038050236
A7: Birkenstock | B7: =SUMIF('Inventory Master'!$E$2:$E$525,$A7,'Inventory Master'!$T$2:$T$525) -> 11 | C7: =SUMIF('Inventory Master'!$E$2:$E$525,$A7,'Inventory Master'!$U$2:$U$525) -> 0 | D7: =SUMIF('Inventory Master'!$E$2:$E$525,$A7,'Inventory Master'!$V$2:$V$525) -> 25 | E7: =SUMIF('Inventory Master'!$E$2:$E$525,$A7,'Inventory Master'!$W$2:$W$525) -> 0 | F7: =SUM(B7:E7) -> 36 | G7: =IFERROR(F7/F$28,0) -> 0.0089529968
A8: Brooks | B8: =SUMIF('Inventory Master'!$E$2:$E$525,$A8,'Inventory Master'!$T$2:$T$525) -> 36 | C8: =SUMIF('Inventory Master'!$E$2:$E$525,$A8,'Inventory Master'!$U$2:$U$525) -> 23 | D8: =SUMIF('Inventory Master'!$E$2:$E$525,$A8,'Inventory Master'!$V$2:$V$525) -> 56 | E8: =SUMIF('Inventory Master'!$E$2:$E$525,$A8,'Inventory Master'!$W$2:$W$525) -> 21 | F8: =SUM(B8:E8) -> 136 | G8: =IFERROR(F8/F$28,0) -> 0.033822432
A9: Converse | B9: =SUMIF('Inventory Master'!$E$2:$E$525,$A9,'Inventory Master'!$T$2:$T$525) -> 42 | C9: =SUMIF('Inventory Master'!$E$2:$E$525,$A9,'Inventory Master'!$U$2:$U$525) -> 8 | D9: =SUMIF('Inventory Master'!$E$2:$E$525,$A9,'Inventory Master'!$V$2:$V$525) -> 68 | E9: =SUMIF('Inventory Master'!$E$2:$E$525,$A9,'Inventory Master'!$W$2:$W$525) -> 7 | F9: =SUM(B9:E9) -> 125 | G9: =IFERROR(F9/F$28,0) -> 0.031086794
A10: Crocs | B10: =SUMIF('Inventory Master'!$E$2:$E$525,$A10,'Inventory Master'!$T$2:$T$525) -> 32 | C10: =SUMIF('Inventory Master'!$E$2:$E$525,$A10,'Inventory Master'!$U$2:$U$525) -> 17 | D10: =SUMIF('Inventory Master'!$E$2:$E$525,$A10,'Inventory Master'!$V$2:$V$525) -> 41 | E10: =SUMIF('Inventory Master'!$E$2:$E$525,$A10,'Inventory Master'!$W$2:$W$525) -> 20 | F10: =SUM(B10:E10) -> 110 | G10: =IFERROR(F10/F$28,0) -> 0.027356379
A11: Fila | B11: =SUMIF('Inventory Master'!$E$2:$E$525,$A11,'Inventory Master'!$T$2:$T$525) -> 0 | C11: =SUMIF('Inventory Master'!$E$2:$E$525,$A11,'Inventory Master'!$U$2:$U$525) -> 0 | D11: =SUMIF('Inventory Master'!$E$2:$E$525,$A11,'Inventory Master'!$V$2:$V$525) -> 12 | E11: =SUMIF('Inventory Master'!$E$2:$E$525,$A11,'Inventory Master'!$W$2:$W$525) -> 0 | F11: =SUM(B11:E11) -> 12 | G11: =IFERROR(F11/F$28,0) -> 0.0029843323
A12: HOKA | B12: =SUMIF('Inventory Master'!$E$2:$E$525,$A12,'Inventory Master'!$T$2:$T$525) -> 43 | C12: =SUMIF('Inventory Master'!$E$2:$E$525,$A12,'Inventory Master'!$U$2:$U$525) -> 28 | D12: =SUMIF('Inventory Master'!$E$2:$E$525,$A12,'Inventory Master'!$V$2:$V$525) -> 54 | E12: =SUMIF('Inventory Master'!$E$2:$E$525,$A12,'Inventory Master'!$W$2:$W$525) -> 12 | F12: =SUM(B12:E12) -> 137 | G12: =IFERROR(F12/F$28,0) -> 0.034071127
A13: Jordan | B13: =SUMIF('Inventory Master'!$E$2:$E$525,$A13,'Inventory Master'!$T$2:$T$525) -> 78 | C13: =SUMIF('Inventory Master'!$E$2:$E$525,$A13,'Inventory Master'!$U$2:$U$525) -> 34 | D13: =SUMIF('Inventory Master'!$E$2:$E$525,$A13,'Inventory Master'!$V$2:$V$525) -> 146 | E13: =SUMIF('Inventory Master'!$E$2:$E$525,$A13,'Inventory Master'!$W$2:$W$525) -> 32 | F13: =SUM(B13:E13) -> 290 | G13: =IFERROR(F13/F$28,0) -> 0.072121363
A14: Mizuno | B14: =SUMIF('Inventory Master'!$E$2:$E$525,$A14,'Inventory Master'!$T$2:$T$525) -> 17 | C14: =SUMIF('Inventory Master'!$E$2:$E$525,$A14,'Inventory Master'!$U$2:$U$525) -> 3 | D14: =SUMIF('Inventory Master'!$E$2:$E$525,$A14,'Inventory Master'!$V$2:$V$525) -> 24 | E14: =SUMIF('Inventory Master'!$E$2:$E$525,$A14,'Inventory Master'!$W$2:$W$525) -> 0 | F14: =SUM(B14:E14) -> 44 | G14: =IFERROR(F14/F$28,0) -> 0.010942552
A15: New Balance | B15: =SUMIF('Inventory Master'!$E$2:$E$525,$A15,'Inventory Master'!$T$2:$T$525) -> 111 | C15: =SUMIF('Inventory Master'!$E$2:$E$525,$A15,'Inventory Master'!$U$2:$U$525) -> 77 | D15: =SUMIF('Inventory Master'!$E$2:$E$525,$A15,'Inventory Master'!$V$2:$V$525) -> 187 | E15: =SUMIF('Inventory Master'!$E$2:$E$525,$A15,'Inventory Master'!$W$2:$W$525) -> 40 | F15: =SUM(B15:E15) -> 415 | G15: =IFERROR(F15/F$28,0) -> 0.10320816
A16: Nike | B16: =SUMIF('Inventory Master'!$E$2:$E$525,$A16,'Inventory Master'!$T$2:$T$525) -> 263 | C16: =SUMIF('Inventory Master'!$E$2:$E$525,$A16,'Inventory Master'!$U$2:$U$525) -> 149 | D16: =SUMIF('Inventory Master'!$E$2:$E$525,$A16,'Inventory Master'!$V$2:$V$525) -> 394 | E16: =SUMIF('Inventory Master'!$E$2:$E$525,$A16,'Inventory Master'!$W$2:$W$525) -> 70 | F16: =SUM(B16:E16) -> 876 | G16: =IFERROR(F16/F$28,0) -> 0.21785625
A17: On | B17: =SUMIF('Inventory Master'!$E$2:$E$525,$A17,'Inventory Master'!$T$2:$T$525) -> 21 | C17: =SUMIF('Inventory Master'!$E$2:$E$525,$A17,'Inventory Master'!$U$2:$U$525) -> 20 | D17: =SUMIF('Inventory Master'!$E$2:$E$525,$A17,'Inventory Master'!$V$2:$V$525) -> 41 | E17: =SUMIF('Inventory Master'!$E$2:$E$525,$A17,'Inventory Master'!$W$2:$W$525) -> 6 | F17: =SUM(B17:E17) -> 88 | G17: =IFERROR(F17/F$28,0) -> 0.021885103
... A27: adidas Originals | B27: =SUMIF('Inventory Master'!$E$2:$E$525,$A27,'Inventory Master'!$T$2:$T$525) -> 90 | C27: =SUMIF('Inventory Master'!$E$2:$E$525,$A27,'Inventory Master'!$U$2:$U$525) -> 77 | D27: =SUMIF('Inventory Master'!$E$2:$E$525,$A27,'Inventory Master'!$V$2:$V$525) -> 136 | E27: =SUMIF('Inventory Master'!$E$2:$E$525,$A27,'Inventory Master'!$W$2:$W$525) -> 36 | F27: =SUM(B27:E27) -> 339 | G27: =IFERROR(F27/F$28,0) -> 0.084307386
A28: Total | B28: =SUM(B6:B27) -> 1152 | C28: =SUM(C6:C27) -> 663 | D28: =SUM(D6:D27) -> 1831 | E28: =SUM(E6:E27) -> 375 | F28: =SUM(F6:F27) -> 4021 | G28: =IFERROR(F28/F28,0) -> 1
A31: Units On Hand by Category
A32: Category | B32: Store 0146 | C32: Store 1382 | D32: Store 2071 | E32: Store 3719 | F32: All Stores | G32: % of Chain
A33: Baseball | B33: =SUMIF('Inventory Master'!$I$2:$I$525,$A33,'Inventory Master'!$T$2:$T$525) -> 12 | C33: =SUMIF('Inventory Master'!$I$2:$I$525,$A33,'Inventory Master'!$U$2:$U$525) -> 3 | D33: =SUMIF('Inventory Master'!$I$2:$I$525,$A33,'Inventory Master'!$V$2:$V$525) -> 20 | E33: =SUMIF('Inventory Master'!$I$2:$I$525,$A33,'Inventory Master'!$W$2:$W$525) -> 0 | F33: =SUM(B33:E33) -> 35 | G33: =IFERROR(F33/F$39,0) -> 0.0087043024
A34: Basketball | B34: =SUMIF('Inventory Master'!$I$2:$I$525,$A34,'Inventory Master'!$T$2:$T$525) -> 106 | C34: =SUMIF('Inventory Master'!$I$2:$I$525,$A34,'Inventory Master'!$U$2:$U$525) -> 98 | D34: =SUMIF('Inventory Master'!$I$2:$I$525,$A34,'Inventory Master'!$V$2:$V$525) -> 176 | E34: =SUMIF('Inventory Master'!$I$2:$I$525,$A34,'Inventory Master'!$W$2:$W$525) -> 22 | F34: =SUM(B34:E34) -> 402 | G34: =IFERROR(F34/F$39,0) -> 0.099975131
A35: Casual | B35: =SUMIF('Inventory Master'!$I$2:$I$525,$A35,'Inventory Master'!$T$2:$T$525) -> 619 | C35: =SUMIF('Inventory Master'!$I$2:$I$525,$A35,'Inventory Master'!$U$2:$U$525) -> 315 | D35: =SUMIF('Inventory Master'!$I$2:$I$525,$A35,'Inventory Master'!$V$2:$V$525) -> 939 | E35: =SUMIF('Inventory Master'!$I$2:$I$525,$A35,'Inventory Master'!$W$2:$W$525) -> 204 | F35: =SUM(B35:E35) -> 2077 | G35: =IFERROR(F35/F$39,0) -> 0.51653817
A36: Running | B36: =SUMIF('Inventory Master'!$I$2:$I$525,$A36,'Inventory Master'!$T$2:$T$525) -> 315 | C36: =SUMIF('Inventory Master'!$I$2:$I$525,$A36,'Inventory Master'!$U$2:$U$525) -> 200 | D36: =SUMIF('Inventory Master'!$I$2:$I$525,$A36,'Inventory Master'!$V$2:$V$525) -> 523 | E36: =SUMIF('Inventory Master'!$I$2:$I$525,$A36,'Inventory Master'!$W$2:$W$525) -> 122 | F36: =SUM(B36:E36) -> 1160 | G36: =IFERROR(F36/F$39,0) -> 0.28848545
A37: Sandals | B37: =SUMIF('Inventory Master'!$I$2:$I$525,$A37,'Inventory Master'!$T$2:$T$525) -> 79 | C37: =SUMIF('Inventory Master'!$I$2:$I$525,$A37,'Inventory Master'!$U$2:$U$525) -> 30 | D37: =SUMIF('Inventory Master'!$I$2:$I$525,$A37,'Inventory Master'!$V$2:$V$525) -> 111 | E37: =SUMIF('Inventory Master'!$I$2:$I$525,$A37,'Inventory Master'!$W$2:$W$525) -> 21 | F37: =SUM(B37:E37) -> 241 | G37: =IFERROR(F37/F$39,0) -> 0.059935339
A38: Training | B38: =SUMIF('Inventory Master'!$I$2:$I$525,$A38,'Inventory Master'!$T$2:$T$525) -> 21 | C38: =SUMIF('Inventory Master'!$I$2:$I$525,$A38,'Inventory Master'!$U$2:$U$525) -> 17 | D38: =SUMIF('Inventory Master'!$I$2:$I$525,$A38,'Inventory Master'!$V$2:$V$525) -> 62 | E38: =SUMIF('Inventory Master'!$I$2:$I$525,$A38,'Inventory Master'!$W$2:$W$525) -> 6 | F38: =SUM(B38:E38) -> 106 | G38: =IFERROR(F38/F$39,0) -> 0.026361602
A39: Total | B39: =SUM(B33:B38) -> 1152 | C39: =SUM(C33:C38) -> 663 | D39: =SUM(D33:D38) -> 1831 | E39: =SUM(E33:E38) -> 375 | F39: =SUM(F33:F38) -> 4021 | G39: =IFERROR(F39/F39,0) -> 1
A42: Units On Hand by Gender / Size Range
A43: Gender | B43: Store 0146 | C43: Store 1382 | D43: Store 2071 | E43: Store 3719 | F43: All Stores | G43: % of Chain
A44: Big Kids | B44: =SUMIF('Inventory Master'!$K$2:$K$525,$A44,'Inventory Master'!$T$2:$T$525) -> 109 | C44: =SUMIF('Inventory Master'!$K$2:$K$525,$A44,'Inventory Master'!$U$2:$U$525) -> 53 | D44: =SUMIF('Inventory Master'!$K$2:$K$525,$A44,'Inventory Master'!$V$2:$V$525) -> 170 | E44: =SUMIF('Inventory Master'!$K$2:$K$525,$A44,'Inventory Master'!$W$2:$W$525) -> 36 | F44: =SUM(B44:E44) -> 368 | G44: =IFERROR(F44/F$49,0) -> 0.091519523
A45: Little Kids | B45: =SUMIF('Inventory Master'!$K$2:$K$525,$A45,'Inventory Master'!$T$2:$T$525) -> 35 | C45: =SUMIF('Inventory Master'!$K$2:$K$525,$A45,'Inventory Master'!$U$2:$U$525) -> 14 | D45: =SUMIF('Inventory Master'!$K$2:$K$525,$A45,'Inventory Master'!$V$2:$V$525) -> 60 | E45: =SUMIF('Inventory Master'!$K$2:$K$525,$A45,'Inventory Master'!$W$2:$W$525) -> 29 | F45: =SUM(B45:E45) -> 138 | G45: =IFERROR(F45/F$49,0) -> 0.034319821
A46: Men | B46: =SUMIF('Inventory Master'!$K$2:$K$525,$A46,'Inventory Master'!$T$2:$T$525) -> 556 | C46: =SUMIF('Inventory Master'!$K$2:$K$525,$A46,'Inventory Master'!$U$2:$U$525) -> 339 | D46: =SUMIF('Inventory Master'!$K$2:$K$525,$A46,'Inventory Master'!$V$2:$V$525) -> 924 | E46: =SUMIF('Inventory Master'!$K$2:$K$525,$A46,'Inventory Master'!$W$2:$W$525) -> 168 | F46: =SUM(B46:E46) -> 1987 | G46: =IFERROR(F46/F$49,0) -> 0.49415568
A47: Unisex | B47: =SUMIF('Inventory Master'!$K$2:$K$525,$A47,'Inventory Master'!$T$2:$T$525) -> 147 | C47: =SUMIF('Inventory Master'!$K$2:$K$525,$A47,'Inventory Master'!$U$2:$U$525) -> 51 | D47: =SUMIF('Inventory Master'!$K$2:$K$525,$A47,'Inventory Master'!$V$2:$V$525) -> 199 | E47: =SUMIF('Inventory Master'!$K$2:$K$525,$A47,'Inventory Master'!$W$2:$W$525) -> 54 | F47: =SUM(B47:E47) -> 451 | G47: =IFERROR(F47/F$49,0) -> 0.11216115
A48: Women | B48: =SUMIF('Inventory Master'!$K$2:$K$525,$A48,'Inventory Master'!$T$2:$T$525) -> 305 | C48: =SUMIF('Inventory Master'!$K$2:$K$525,$A48,'Inventory Master'!$U$2:$U$525) -> 206 | D48: =SUMIF('Inventory Master'!$K$2:$K$525,$A48,'Inventory Master'!$V$2:$V$525) -> 478 | E48: =SUMIF('Inventory Master'!$K$2:$K$525,$A48,'Inventory Master'!$W$2:$W$525) -> 88 | F48: =SUM(B48:E48) -> 1077 | G48: =IFERROR(F48/F$49,0) -> 0.26784382
A49: Total | B49: =SUM(B44:B48) -> 1152 | C49: =SUM(C44:C48) -> 663 | D49: =SUM(D44:D48) -> 1831 | E49: =SUM(E44:E48) -> 375 | F49: =SUM(F44:F48) -> 4021 | G49: =IFERROR(F49/F49,0) -> 1
